Workbook

Sheet Products
A1: Product id | B1: Product Name | C1: Category | D1: Brand | E1: Price | F1: Stock
A2: P1001 | B2: Laptop | C2: Electronics | D2: Dell | E2: 55000 | F2: 25 | H2: Task-1 | I2: Find the Product Name for Product ID P1006.
A3: P1002 | B3: Smartphone | C3: Electronics | D3: Samsung | E3: 32000 | F3: 40 | J3: Product id | K3: Product name
A4: P1003 | B4: Headphones | C4: Electronics | D4: Sony | E4: 4500 | F4: 80 | J4: P1006 | K4: =INDEX(product[Product Name],MATCH(J4,product[Product id],0)) -> Printer
A5: P1004 | B5: Keyboard | C5: Accessories | D5: Logitech | E5: 1800 | F5: 65
A6: P1005 | B6: Mouse | C6: Accessories | D6: HP | E6: 900 | F6: 120 | H6: Task-2 | I6: Find the Price for Product ID P1008.
A7: P1006 | B7: Printer | C7: Electronics | D7: Canon | E7: 12500 | F7: 18
A8: P1007 | B8: Office Chair | C8: Furniture | D8: Green Soul | E8: 8500 | F8: 20 | J8: Product id | K8: Price
A9: P1008 | B9: Office Desk | C9: Furniture | D9: IKEA | E9: 12000 | F9: 15 | J9: P1008 | K9: =INDEX(product[Price],MATCH(J9,product[Product id],0)) -> 12000
A10: P1009 | B10: Monitor | C10: Electronics | D10: LG | E10: 16000 | F10: 30
A11: P1010 | B11: Webcam | C11: Accessories | D11: Logitech | E11: 3500 | F11: 50
H12: Task-3 | I12: Find the Brand for Product ID P1003.
J14: Product id | K14: Brand
A15: Task-5 | B15: Find the Category for Product ID P1004. | J15: P1003 | K15: =INDEX(product[Brand],MATCH(J15,product[Product id],0)) -> Sony
B17: Product id | C17: Category
B18: P1004 | C18: =INDEX(product[Category],MATCH(B18,product[Product id],0)) -> Accessories | H18: Task-4 | I18: Find the Stock for Product ID P1005.
J20: Product id | K20: Stock
J21: P1005 | K21: =INDEX(product[Stock],MATCH(J21,product[Product id],0)) -> 120

Sheet Customers
A1: Customer ID | B1: Customer Name | C1: City | D1: State | E1: Gender
A2: C001 | B2: Amit Patel | C2: Ahmedabad | D2: Gujarat | E2: Male | H2: Task-6 | I2: Find the Customer Name for C007.
A3: C002 | B3: Priya Shah | C3: Surat | D3: Gujarat | E3: Female
A4: C003 | B4: Rahul Mehta | C4: Mumbai | D4: Maharashtra | E4: Male | J4: Customer id | K4: Customer name
A5: C004 | B5: Sneha Joshi | C5: Pune | D5: Maharashtra | E5: Female | J5: C007 | K5: =INDEX(customers[Customer Name],MATCH(J5,customers[Customer ID],0)) -> Rohan Gupta
A6: C005 | B6: Arjun Singh | C6: Jaipur | D6: Rajasthan | E6: Male
A7: C006 | B7: Neha Verma | C7: Delhi | D7: Delhi | E7: Female
A8: C007 | B8: Rohan Gupta | C8: Indore | D8: Madhya Pradesh | E8: Male | H8: Task-7 | I8: Find the City for C010.
A9: C008 | B9: Pooja Sharma | C9: Lucknow | D9: Uttar Pradesh | E9: Female
A10: C009 | B10: Karan Desai | C10: Vadodara | D10: Gujarat | E10: Male | J10: Customer id | K10: City
A11: C010 | B11: Anjali Nair | C11: Kochi | D11: Kerala | E11: Female | J11: C010 | K11: =INDEX(customers[City],MATCH(J11,customers[Customer ID],0)) -> Kochi
H14: Task-8 | I14: Find the State for C003.
J16: Customer id | K16: State
J17: C003 | K17: =INDEX(customers[State],MATCH(J17,customers[Customer ID],0)) -> Maharashtra
H20: Task-9 | I20: Find the Gender for C006.
J22: Customer id | K22: Gender
J23: C003 | K23: =INDEX(customers[Gender],MATCH(J23,customers[Customer ID],0)) -> Male

Sheet Stores
A1: Store ID | B1: Store Name | C1: City | D1: State
A2: S001 | B2: Alpha Store | C2: Ahmedabad | D2: Gujarat | F2: Task-10 | G2: Find the Store Name for S003.
A3: S002 | B3: Beta Store | C3: Surat | D3: Gujarat
A4: S003 | B4: Central Store | C4: Mumbai | D4: Maharashtra | G4: Store id | H4: Store name
A5: S004 | B5: Digital Hub | C5: Pune | D5: Maharashtra | G5: S003 | H5: =INDEX(store[Store Name],MATCH(G5,store[Store ID],0)) -> Central Store
A6: S005 | B6: Smart World | C6: Jaipur | D6: Rajasthan
F8: Task-11 | G8: Find the Store City for S005.
G10: Store id | H10: City
G11: S005 | H11: =INDEX(store[City],MATCH(G11,store[Store ID],0)) -> Jaipur
F14: Task-12 | G14: Find the Store State for S002.
G16: Store id | H16: State
G17: S002 | H17: =INDEX(store[State],MATCH(G17,store[Store ID],0)) -> Gujarat

Sheet Sales
A1: Sale ID | B1: Product ID | C1: Customer ID | D1: Quantity | E1: Date | F1: Store ID
A2: SA001 | B2: P1001 | C2: C001 | D2: 1 | E2: 46023 | F2: S001 | I2: Task-13 | J2: Retrieve the Product Name for every Product ID in the Sales sheet
A3: SA002 | B3: P1005 | C3: C002 | D3: 3 | E3: 46024 | F3: S002 | K3: Product id | L3: Product name
A4: SA003 | B4: P1003 | C4: C003 | D4: 2 | E4: 46025 | F4: S003 | K4: {=_xlfn.UNIQUE(Sales[Product ID])} -> P1001 | L4: =INDEX(product[Product Name],MATCH(Sales!$K4,product[Product id],0)) -> Laptop
A5: SA004 | B5: P1009 | C5: C004 | D5: 1 | E5: 46026 | F5: S004 | K5: P1005 | L5: =INDEX(product[Product Name],MATCH(Sales!$K5,product[Product id],0)) -> Mouse
A6: SA005 | B6: P1002 | C6: C005 | D6: 2 | E6: 46027 | F6: S005 | K6: P1003 | L6: =INDEX(product[Product Name],MATCH(Sales!$K6,product[Product id],0)) -> Headphones
A7: SA006 | B7: P1007 | C7: C006 | D7: 1 | E7: 46028 | F7: S001 | K7: P1009 | L7: =INDEX(product[Product Name],MATCH(Sales!$K7,product[Product id],0)) -> Monitor
A8: SA007 | B8: P1006 | C8: C007 | D8: 1 | E8: 46029 | F8: S002 | K8: P1002 | L8: =INDEX(product[Product Name],MATCH(Sales!$K8,product[Product id],0)) -> Smartphone
A9: SA008 | B9: P1010 | C9: C008 | D9: 2 | E9: 46030 | F9: S003 | K9: P1007 | L9: =INDEX(product[Product Name],MATCH(Sales!$K9,product[Product id],0)) -> Office Chair
A10: SA009 | B10: P1004 | C10: C009 | D10: 4 | E10: 46031 | F10: S004 | K10: P1006 | L10: =INDEX(product[Product Name],MATCH(Sales!$K10,product[Product id],0)) -> Printer
A11: SA010 | B11: P1008 | C11: C010 | D11: 1 | E11: 46032 | F11: S005 | K11: P1010 | L11: =INDEX(product[Product Name],MATCH(Sales!$K11,product[Product id],0)) -> Webcam
A12: SA011 | B12: P1005 | C12: C001 | D12: 5 | E12: 46033 | F12: S001 | K12: P1004 | L12: =INDEX(product[Product Name],MATCH(Sales!$K12,product[Product id],0)) -> Keyboard
A13: SA012 | B13: P1003 | C13: C002 | D13: 3 | E13: 46034 | F13: S002 | K13: P1008 | L13: =INDEX(product[Product Name],MATCH(Sales!$K13,product[Product id],0)) -> Office Desk
A14: SA013 | B14: P1001 | C14: C003 | D14: 1 | E14: 46035 | F14: S003
A15: SA014 | B15: P1009 | C15: C004 | D15: 2 | E15: 46036 | F15: S004 | I15: Task-14 | J15: Retrieve the Customer Name for every Customer ID in the Sales sheet.
A16: SA015 | B16: P1002 | C16: C005 | D16: 1 | E16: 46037 | F16: S005 | K16: Customer id | L16: Customer name
K17: {=_xlfn.UNIQUE(Sales[Customer ID])} -> C001 | L17: =INDEX(customers[Customer Name],MATCH(Sales!$K17,customers[Customer ID],0)) -> Amit Patel
K18: C002 | L18: =INDEX(customers[Customer Name],MATCH(Sales!$K18,customers[Customer ID],0)) -> Priya Shah
K19: C003 | L19: =INDEX(customers[Customer Name],MATCH(Sales!$K19,customers[Customer ID],0)) -> Rahul Mehta
K20: C004 | L20: =INDEX(customers[Customer Name],MATCH(Sales!$K20,customers[Customer ID],0)) -> Sneha Joshi
K21: C005 | L21: =INDEX(customers[Customer Name],MATCH(Sales!$K21,customers[Customer ID],0)) -> Arjun Singh
K22: C006 | L22: =INDEX(customers[Customer Name],MATCH(Sales!$K22,customers[Customer ID],0)) -> Neha Verma
K23: C007 | L23: =INDEX(customers[Customer Name],MATCH(Sales!$K23,customers[Customer ID],0)) -> Rohan Gupta
K24: C008 | L24: =INDEX(customers[Customer Name],MATCH(Sales!$K24,customers[Customer ID],0)) -> Pooja Sharma
K25: C009 | L25: =INDEX(customers[Customer Name],MATCH(Sales!$K25,customers[Customer ID],0)) -> Karan Desai
K26: C010 | L26: =INDEX(customers[Customer Name],MATCH(Sales!$K26,customers[Customer ID],0)) -> Anjali Nair
I29: Task-15 | J29: Retrieve the Store Name for every Store ID in the Sales sheet.
K31: Store id | L31: Store name
K32: {=_xlfn.UNIQUE(Sales[Store ID])} -> S001 | L32: =INDEX(store[Store Name],MATCH(Sales!$K32,store[Store ID],0)) -> Alpha Store
K33: S002 | L33: =INDEX(store[Store Name],MATCH(Sales!$K33,store[Store ID],0)) -> Beta Store
K34: S003 | L34: =INDEX(store[Store Name],MATCH(Sales!$K34,store[Store ID],0)) -> Central Store
K35: S004 | L35: =INDEX(store[Store Name],MATCH(Sales!$K35,store[Store ID],0)) -> Digital Hub
K36: S005 | L36: =INDEX(store[Store Name],MATCH(Sales!$K36,store[Store ID],0)) -> Smart World
I39: Task-16 | J39: Retrieve the Product Price for every Product ID in the Sales sheet.
K41: Product ID | L41: Product price
K42: P1001 | L42: =INDEX(product[Price],MATCH(Sales!$K42,product[Product id],0)) -> 55000
K43: P1005 | L43: =INDEX(product[Price],MATCH(Sales!$K43,product[Product id],0)) -> 900
K44: P1003 | L44: =INDEX(product[Price],MATCH(Sales!$K44,product[Product id],0)) -> 4500
K45: P1009 | L45: =INDEX(product[Price],MATCH(Sales!$K45,product[Product id],0)) -> 16000
K46: P1002 | L46: =INDEX(product[Price],MATCH(Sales!$K46,product[Product id],0)) -> 32000
...

Sheet Index-Match
A2: Task-18 | C2: Create a report with: | F2: Sale ID | G2: Product Name | H2: Category | I2: Customer name | J2: Store name | K2: Qty | L2: Price | M2: Total sale
C3: Sale ID | F3: SA001 | G3: =INDEX('Advance table'!K3:K17,MATCH('Index-Match'!F3,'Advance table'!H3:H17,0)) -> Laptop | H3: =INDEX(Table7[Category],MATCH('Index-Match'!G3,Table7[Product Name],0)) -> Electronics | I3: =INDEX(Table7[Customer Name],MATCH(F3,Table7[Sale ID],0)) -> Amit Patel | J3: =INDEX(Table7[Store name],MATCH('Index-Match'!I3,Table7[Customer Name],0)) -> Alpha Store | K3: =INDEX(Table7[Quantity],MATCH('Index-Match'!F3,Table7[Sale ID],0)) -> 1 | L3: =INDEX(Table7[Product price],MATCH('Index-Match'!F3,Table7[Sale ID],0)) -> 55000 | M3: =INDEX(Table7[Total sale],MATCH('Index-Match'!F3,Table7[Sale ID],0)) -> 55000
C4: Product Name | F4: SA002 | G4: =INDEX('Advance table'!K4:K18,MATCH('Index-Match'!F4,'Advance table'!H4:H18,0)) -> Mouse | H4: =INDEX(Table7[Category],MATCH('Index-Match'!G4,Table7[Product Name],0)) -> Accessories | I4: =INDEX(Table7[Customer Name],MATCH(F4,Table7[Sale ID],0)) -> Priya Shah | J4: =INDEX(Table7[Store name],MATCH('Index-Match'!I4,Table7[Customer Name],0)) -> Beta Store | K4: =INDEX(Table7[Quantity],MATCH('Index-Match'!F4,Table7[Sale ID],0)) -> 3 | L4: =INDEX(Table7[Product price],MATCH('Index-Match'!F4,Table7[Sale ID],0)) -> 900 | M4: =INDEX(Table7[Total sale],MATCH('Index-Match'!F4,Table7[Sale ID],0)) -> 2700
C5: Category | F5: SA003 | G5: =INDEX('Advance table'!K5:K19,MATCH('Index-Match'!F5,'Advance table'!H5:H19,0)) -> Headphones | H5: =INDEX(Table7[Category],MATCH('Index-Match'!G5,Table7[Product Name],0)) -> Electronics | I5: =INDEX(Table7[Customer Name],MATCH(F5,Table7[Sale ID],0)) -> Rahul Mehta | J5: =INDEX(Table7[Store name],MATCH('Index-Match'!I5,Table7[Customer Name],0)) -> Central Store | K5: =INDEX(Table7[Quantity],MATCH('Index-Match'!F5,Table7[Sale ID],0)) -> 2 | L5: =INDEX(Table7[Product price],MATCH('Index-Match'!F5,Table7[Sale ID],0)) -> 4500 | M5: =INDEX(Table7[Total sale],MATCH('Index-Match'!F5,Table7[Sale ID],0)) -> 9000
C6: Customer Name | F6: SA004 | G6: =INDEX('Advance table'!K6:K20,MATCH('Index-Match'!F6,'Advance table'!H6:H20,0)) -> Monitor | H6: =INDEX(Table7[Category],MATCH('Index-Match'!G6,Table7[Product Name],0)) -> Electronics | I6: =INDEX(Table7[Customer Name],MATCH(F6,Table7[Sale ID],0)) -> Sneha Joshi | J6: =INDEX(Table7[Store name],MATCH('Index-Match'!I6,Table7[Customer Name],0)) -> Digital Hub | K6: =INDEX(Table7[Quantity],MATCH('Index-Match'!F6,Table7[Sale ID],0)) -> 1 | L6: =INDEX(Table7[Product price],MATCH('Index-Match'!F6,Table7[Sale ID],0)) -> 16000 | M6: =INDEX(Table7[Total sale],MATCH('Index-Match'!F6,Table7[Sale ID],0)) -> 16000
C7: Store Name | F7: SA005 | G7: =INDEX('Advance table'!K7:K21,MATCH('Index-Match'!F7,'Advance table'!H7:H21,0)) -> Smartphone | H7: =INDEX(Table7[Category],MATCH('Index-Match'!G7,Table7[Product Name],0)) -> Electronics | I7: =INDEX(Table7[Customer Name],MATCH(F7,Table7[Sale ID],0)) -> Arjun Singh | J7: =INDEX(Table7[Store name],MATCH('Index-Match'!I7,Table7[Customer Name],0)) -> Smart World | K7: =INDEX(Table7[Quantity],MATCH('Index-Match'!F7,Table7[Sale ID],0)) -> 2 | L7: =INDEX(Table7[Product price],MATCH('Index-Match'!F7,Table7[Sale ID],0)) -> 32000 | M7: =INDEX(Table7[Total sale],MATCH('Index-Match'!F7,Table7[Sale ID],0)) -> 64000
C8: Quantity | F8: SA006 | G8: =INDEX('Advance table'!K8:K22,MATCH('Index-Match'!F8,'Advance table'!H8:H22,0)) -> Office Chair | H8: =INDEX(Table7[Category],MATCH('Index-Match'!G8,Table7[Product Name],0)) -> Furniture | I8: =INDEX(Table7[Customer Name],MATCH(F8,Table7[Sale ID],0)) -> Neha Verma | J8: =INDEX(Table7[Store name],MATCH('Index-Match'!I8,Table7[Customer Name],0)) -> Alpha Store | K8: =INDEX(Table7[Quantity],MATCH('Index-Match'!F8,Table7[Sale ID],0)) -> 1 | L8: =INDEX(Table7[Product price],MATCH('Index-Match'!F8,Table7[Sale ID],0)) -> 8500 | M8: =INDEX(Table7[Total sale],MATCH('Index-Match'!F8,Table7[Sale ID],0)) -> 8500
C9: Price | F9: SA007 | G9: =INDEX('Advance table'!K9:K23,MATCH('Index-Match'!F9,'Advance table'!H9:H23,0)) -> Printer | H9: =INDEX(Table7[Category],MATCH('Index-Match'!G9,Table7[Product Name],0)) -> Electronics | I9: =INDEX(Table7[Customer Name],MATCH(F9,Table7[Sale ID],0)) -> Rohan Gupta | J9: =INDEX(Table7[Store name],MATCH('Index-Match'!I9,Table7[Customer Name],0)) -> Beta Store | K9: =INDEX(Table7[Quantity],MATCH('Index-Match'!F9,Table7[Sale ID],0)) -> 1 | L9: =INDEX(Table7[Product price],MATCH('Index-Match'!F9,Table7[Sale ID],0)) -> 12500 | M9: =INDEX(Table7[Total sale],MATCH('Index-Match'!F9,Table7[Sale ID],0)) -> 12500
C10: Total Sales | F10: SA008 | G10: =INDEX('Advance table'!K10:K24,MATCH('Index-Match'!F10,'Advance table'!H10:H24,0)) -> Webcam | H10: =INDEX(Table7[Category],MATCH('Index-Match'!G10,Table7[Product Name],0)) -> Accessories | I10: =INDEX(Table7[Customer Name],MATCH(F10,Table7[Sale ID],0)) -> Pooja Sharma | J10: =INDEX(Table7[Store name],MATCH('Index-Match'!I10,Table7[Customer Name],0)) -> Central Store | K10: =INDEX(Table7[Quantity],MATCH('Index-Match'!F10,Table7[Sale ID],0)) -> 2 | L10: =INDEX(Table7[Product price],MATCH('Index-Match'!F10,Table7[Sale ID],0)) -> 3500 | M10: =INDEX(Table7[Total sale],MATCH('Index-Match'!F10,Table7[Sale ID],0)) -> 7000
F11: SA009 | G11: =INDEX('Advance table'!K11:K25,MATCH('Index-Match'!F11,'Advance table'!H11:H25,0)) -> Keyboard | H11: =INDEX(Table7[Category],MATCH('Index-Match'!G11,Table7[Product Name],0)) -> Accessories | I11: =INDEX(Table7[Customer Name],MATCH(F11,Table7[Sale ID],0)) -> Karan Desai | J11: =INDEX(Table7[Store name],MATCH('Index-Match'!I11,Table7[Customer Name],0)) -> Digital Hub | K11: =INDEX(Table7[Quantity],MATCH('Index-Match'!F11,Table7[Sale ID],0)) -> 4 | L11: =INDEX(Table7[Product price],MATCH('Index-Match'!F11,Table7[Sale ID],0)) -> 1800 | M11: =INDEX(Table7[Total sale],MATCH('Index-Match'!F11,Table7[Sale ID],0)) -> 7200
F12: SA010 | G12: =INDEX('Advance table'!K12:K26,MATCH('Index-Match'!F12,'Advance table'!H12:H26,0)) -> Office Desk | H12: =INDEX(Table7[Category],MATCH('Index-Match'!G12,Table7[Product Name],0)) -> Furniture | I12: =INDEX(Table7[Customer Name],MATCH(F12,Table7[Sale ID],0)) -> Anjali Nair | J12: =INDEX(Table7[Store name],MATCH('Index-Match'!I12,Table7[Customer Name],0)) -> Smart World | K12: =INDEX(Table7[Quantity],MATCH('Index-Match'!F12,Table7[Sale ID],0)) -> 1 | L12: =INDEX(Table7[Product price],MATCH('Index-Match'!F12,Table7[Sale ID],0)) -> 12000 | M12: =INDEX(Table7[Total sale],MATCH('Index-Match'!F12,Table7[Sale ID],0)) -> 12000
F13: SA011 | G13: =INDEX('Advance table'!K13:K27,MATCH('Index-Match'!F13,'Advance table'!H13:H27,0)) -> Mouse | H13: =INDEX(Table7[Category],MATCH('Index-Match'!G13,Table7[Product Name],0)) -> Accessories | I13: =INDEX(Table7[Customer Name],MATCH(F13,Table7[Sale ID],0)) -> Amit Patel | J13: =INDEX(Table7[Store name],MATCH('Index-Match'!I13,Table7[Customer Name],0)) -> Alpha Store | K13: =INDEX(Table7[Quantity],MATCH('Index-Match'!F13,Table7[Sale ID],0)) -> 5 | L13: =INDEX(Table7[Product price],MATCH('Index-Match'!F13,Table7[Sale ID],0)) -> 900 | M13: =INDEX(Table7[Total sale],MATCH('Index-Match'!F13,Table7[Sale ID],0)) -> 4500
F14: SA012 | G14: =INDEX('Advance table'!K14:K28,MATCH('Index-Match'!F14,'Advance table'!H14:H28,0)) -> Headphones | H14: =INDEX(Table7[Category],MATCH('Index-Match'!G14,Table7[Product Name],0)) -> Electronics | I14: =INDEX(Table7[Customer Name],MATCH(F14,Table7[Sale ID],0)) -> Priya Shah | J14: =INDEX(Table7[Store name],MATCH('Index-Match'!I14,Table7[Customer Name],0)) -> Beta Store | K14: =INDEX(Table7[Quantity],MATCH('Index-Match'!F14,Table7[Sale ID],0)) -> 3 | L14: =INDEX(Table7[Product price],MATCH('Index-Match'!F14,Table7[Sale ID],0)) -> 4500 | M14: =INDEX(Table7[Total sale],MATCH('Index-Match'!F14,Table7[Sale ID],0)) -> 13500
F15: SA013 | G15: =INDEX('Advance table'!K15:K29,MATCH('Index-Match'!F15,'Advance table'!H15:H29,0)) -> Laptop | H15: =INDEX(Table7[Category],MATCH('Index-Match'!G15,Table7[Product Name],0)) -> Electronics | I15: =INDEX(Table7[Customer Name],MATCH(F15,Table7[Sale ID],0)) -> Rahul Mehta | J15: =INDEX(Table7[Store name],MATCH('Index-Match'!I15,Table7[Customer Name],0)) -> Central Store | K15: =INDEX(Table7[Quantity],MATCH('Index-Match'!F15,Table7[Sale ID],0)) -> 1 | L15: =INDEX(Table7[Product price],MATCH('Index-Match'!F15,Table7[Sale ID],0)) -> 55000 | M15: =INDEX(Table7[Total sale],MATCH('Index-Match'!F15,Table7[Sale ID],0)) -> 55000
F16: SA014 | G16: =INDEX('Advance table'!K16:K30,MATCH('Index-Match'!F16,'Advance table'!H16:H30,0)) -> Monitor | H16: =INDEX(Table7[Category],MATCH('Index-Match'!G16,Table7[Product Name],0)) -> Electronics | I16: =INDEX(Table7[Customer Name],MATCH(F16,Table7[Sale ID],0)) -> Sneha Joshi | J16: =INDEX(Table7[Store name],MATCH('Index-Match'!I16,Table7[Customer Name],0)) -> Digital Hub | K16: =INDEX(Table7[Quantity],MATCH('Index-Match'!F16,Table7[Sale ID],0)) -> 2 | L16: =INDEX(Table7[Product price],MATCH('Index-Match'!F16,Table7[Sale ID],0)) -> 16000 | M16: =INDEX(Table7[Total sale],MATCH('Index-Match'!F16,Table7[Sale ID],0)) -> 32000
F17: SA015 | G17: =INDEX('Advance table'!K17:K31,MATCH('Index-Match'!F17,'Advance table'!H17:H31,0)) -> Smartphone | H17: =INDEX(Table7[Category],MATCH('Index-Match'!G17,Table7[Product Name],0)) -> Electronics | I17: =INDEX(Table7[Customer Name],MATCH(F17,Table7[Sale ID],0)) -> Arjun Singh | J17: =INDEX(Table7[Store name],MATCH('Index-Match'!I17,Table7[Customer Name],0)) -> Smart World | K17: =INDEX(Table7[Quantity],MATCH('Index-Match'!F17,Table7[Sale ID],0)) -> 1 | L17: =INDEX(Table7[Product price],MATCH('Index-Match'!F17,Table7[Sale ID],0)) -> 32000 | M17: =INDEX(Table7[Total sale],MATCH('Index-Match'!F17,Table7[Sale ID],0)) -> 32000
A21: Task-19 | C21: Create a Dynamic Product Search.
C22: Input: Product ID | G22: Product ID | H22: Product Name | I22: Category | J22: Brand | K22: Price | L22: Stock
C23: Output: - Product Name - Category - Brand - Price - Stock | G23: P1005 | H23: =INDEX(product[Product Name],MATCH('Index-Match'!G23,product[Product id],0)) -> Mouse | I23: =INDEX(product[Category],MATCH('Index-Match'!H23,product[Product Name],0)) -> Accessories | J23: =INDEX(product[Brand],MATCH('Index-Match'!H23,product[Product Name],0)) -> HP | K23: =INDEX(product[Price],MATCH('Index-Match'!J23,product[Brand],0)) -> 900 | L23: =INDEX(product[Stock],MATCH('Index-Match'!K23,product[Price],0)) -> 120

Sheet Task-20 invoice
B2: Task-20 | D2: Create a Transaction Dashboard. | H2: Sale ID | I2: Product Name | J2: Category | K2: Brand | L2: customer city | M2: store name | N2: Store city | O2: qty | P2: Price | Q2: Total sale | R2: Date
D3: Input: Sale ID | H3: SA014 | I3: =INDEX('Index-Match'!G3:G17,MATCH(H3,'Index-Match'!F3:F17,0)) -> Monitor | J3: =INDEX('Index-Match'!H3:H17,MATCH(I3,'Index-Match'!G3:G17,0)) -> Electronics | K3: =INDEX(product[Brand],MATCH('Task-20 invoice'!I3,product[Product Name],0)) -> LG | L3: =INDEX(customers[City],MATCH('Task-20 invoice'!#REF!,customers[Customer Name],0)) -> #REF! | M3: =INDEX('Index-Match'!J3:J17,MATCH(H3,'Index-Match'!F3:F17,0)) -> Digital Hub | N3: =INDEX(store[City],MATCH('Task-20 invoice'!M3,'Index-Match'!J3:J17,0)) -> Pune | O3: =INDEX(Table7[Quantity],MATCH('Task-20 invoice'!H3,Table7[Sale ID],0)) -> 2 | P3: =INDEX(Table7[Product price],MATCH('Task-20 invoice'!H3,Table7[Sale ID],0)) -> 16000 | Q3: =INDEX(Table7[Total sale],MATCH('Task-20 invoice'!H3,Table7[Sale ID],0)) -> 32000 | R3: =INDEX(Sales[Date],MATCH('Task-20 invoice'!H3,Sales[Sale ID],0)) -> 46036
D4: Display: - Product Name - Category - Brand - Customer Name - Customer City - Store Name - Store City - Quantity - Product Price - Total Sales - Date
G6: Transaction Dashboard
G8: Sale id : | H8: SA003 | J8: Date : | K8: =INDEX(Table7[Date],MATCH('Task-20 invoice'!H8,Table7[Sale ID],0)) -> 46025
G9: Brand : | H9: =INDEX(Table7[Brand],MATCH('Task-20 invoice'!H8,Table7[Sale ID],0)) -> Sony
G10: Store name : | H10: =INDEX(Table7[Store name],MATCH('Task-20 invoice'!H8,Table7[Sale ID],0)) -> Central Store | J10: Customer Name : | K10: =INDEX(Table7[Customer Name],MATCH('Task-20 invoice'!H8,Table7[Sale ID],0)) -> Rahul Mehta
G11: Store City : | H11: =INDEX(Table7[Store City],MATCH('Task-20 invoice'!H10,Table7[Store name],0)) -> Mumbai | J11: Customer City : | K11: =INDEX(Table7[Customer city],MATCH('Task-20 invoice'!K10,Table7[Customer Name],0)) -> Mumbai
G13: Product Name | H13: Category | I13: Qty | J13: Product Price | K13: Total Amount
G14: =INDEX(Table7[Product Name],MATCH('Task-20 invoice'!H8,Table7[Sale ID],0)) -> Headphones | H14: =INDEX(Table7[Category],MATCH('Task-20 invoice'!G14,Table7[Product Name],0)) -> Electronics | I14: =INDEX(Table7[Quantity],MATCH('Task-20 invoice'!H8,Table7[Sale ID],0)) -> 2 | J14: =INDEX(Table7[Product price],MATCH('Task-20 invoice'!H8,Table7[Sale ID],0)) -> 4500 | K14: =INDEX(Table7[Total sale],MATCH('Task-20 invoice'!H8,Table7[Sale ID],0)) -> 9000
J23: Total : | K23: =SUM(K14:K22) -> 9000

Sheet Advance table
B2: Product id | C2: Product Name | D2: Category | E2: Brand | H2: Sale ID | I2: Date | J2: Product ID | K2: Product Name | L2: Category | M2: Brand | N2: Customer ID | O2: Customer Name | P2: Customer city | Q2: Customer State | R2: Customer Gender | S2: Store ID | T2: Store name | U2: Store City | V2: Quantity | W2: Product price | X2: Total sale
B3: P1001 | C3: Laptop | D3: Electronics | E3: Dell | H3: SA001 | I3: =INDEX(Sales[Date],MATCH(Table7[[#This Row],[Sale ID]],Sales[Sale ID],0)) -> 46023 | J3: P1001 | K3: =INDEX(C3:C12,MATCH($J3,B3:B12,0)) -> Laptop | L3: =INDEX(D3:D12,MATCH(K3,C3:C12,0)) -> Electronics | M3: =INDEX($E$3:$E$12,MATCH(Table7[[#This Row],[Product ID]],$B$3:$B$12,0)) -> Dell | N3: C001 | O3: =INDEX($B$17:$B$26,MATCH(N3,$A$17:$A$26,0)) -> Amit Patel | P3: =INDEX($C$17:$C$26,MATCH(Table7[[#This Row],[Customer ID]],$A$17:$A$26,0)) -> Ahmedabad | Q3: =INDEX($D$17:$D$26,MATCH(Table7[[#This Row],[Customer ID]],$A$17:$A$26,0)) -> Gujarat | R3: =INDEX($E$17:$E$26,MATCH(Table7[[#This Row],[Customer ID]],$A$17:$A$26,0)) -> Male | S3: S001 | T3: =INDEX($B$30:$B$34,MATCH(S3,$A$30:$A$34,0)) -> Alpha Store | U3: =INDEX($C$30:$C$34,MATCH(Table7[[#This Row],[Store ID]],'Advance table'!$A$30:$A$34,0)) -> Ahmedabad | V3: 1 | W3: 55000 | X3: 55000
B4: P1002 | C4: Smartphone | D4: Electronics | E4: Samsung | H4: SA002 | I4: =INDEX(Sales[Date],MATCH(Table7[[#This Row],[Sale ID]],Sales[Sale ID],0)) -> 46024 | J4: P1005 | K4: =INDEX(C4:C13,MATCH($J4,B4:B13,0)) -> Mouse | L4: =INDEX(D4:D13,MATCH(K4,C4:C13,0)) -> Accessories | M4: =INDEX($E$3:$E$12,MATCH(Table7[[#This Row],[Product ID]],$B$3:$B$12,0)) -> HP | N4: C002 | O4: =INDEX($B$17:$B$26,MATCH(N4,$A$17:$A$26,0)) -> Priya Shah | P4: =INDEX($C$17:$C$26,MATCH(Table7[[#This Row],[Customer ID]],$A$17:$A$26,0)) -> Surat | Q4: =INDEX($D$17:$D$26,MATCH(Table7[[#This Row],[Customer ID]],$A$17:$A$26,0)) -> Gujarat | R4: =INDEX($E$17:$E$26,MATCH(Table7[[#This Row],[Customer ID]],$A$17:$A$26,0)) -> Female | S4: S002 | T4: =INDEX($B$30:$B$34,MATCH(S4,$A$30:$A$34,0)) -> Beta Store | U4: =INDEX($C$30:$C$34,MATCH(Table7[[#This Row],[Store ID]],'Advance table'!$A$30:$A$34,0)) -> Surat | V4: 3 | W4: 900 | X4: 2700
B5: P1003 | C5: Headphones | D5: Electronics | E5: Sony | H5: SA003 | I5: =INDEX(Sales[Date],MATCH(Table7[[#This Row],[Sale ID]],Sales[Sale ID],0)) -> 46025 | J5: P1003 | K5: =INDEX(C5:C14,MATCH($J5,B5:B14,0)) -> Headphones | L5: =INDEX(D5:D14,MATCH(K5,C5:C14,0)) -> Electronics | M5: =INDEX($E$3:$E$12,MATCH(Table7[[#This Row],[Product ID]],$B$3:$B$12,0)) -> Sony | N5: C003 | O5: =INDEX($B$17:$B$26,MATCH(N5,$A$17:$A$26,0)) -> Rahul Mehta | P5: =INDEX($C$17:$C$26,MATCH(Table7[[#This Row],[Customer ID]],$A$17:$A$26,0)) -> Mumbai | Q5: =INDEX($D$17:$D$26,MATCH(Table7[[#This Row],[Customer ID]],$A$17:$A$26,0)) -> Maharashtra | R5: =INDEX($E$17:$E$26,MATCH(Table7[[#This Row],[Customer ID]],$A$17:$A$26,0)) -> Male | S5: S003 | T5: =INDEX($B$30:$B$34,MATCH(S5,$A$30:$A$34,0)) -> Central Store | U5: =INDEX($C$30:$C$34,MATCH(Table7[[#This Row],[Store ID]],'Advance table'!$A$30:$A$34,0)) -> Mumbai | V5: 2 | W5: 4500 | X5: 9000
B6: P1004 | C6: Keyboard | D6: Accessories | E6: Logitech | H6: SA004 | I6: =INDEX(Sales[Date],MATCH(Table7[[#This Row],[Sale ID]],Sales[Sale ID],0)) -> 46026 | J6: P1009 | K6: =INDEX(C6:C15,MATCH($J6,B6:B15,0)) -> Monitor | L6: =INDEX(D6:D15,MATCH(K6,C6:C15,0)) -> Electronics | M6: =INDEX($E$3:$E$12,MATCH(Table7[[#This Row],[Product ID]],$B$3:$B$12,0)) -> LG | N6: C004 | O6: =INDEX($B$17:$B$26,MATCH(N6,$A$17:$A$26,0)) -> Sneha Joshi | P6: =INDEX($C$17:$C$26,MATCH(Table7[[#This Row],[Customer ID]],$A$17:$A$26,0)) -> Pune | Q6: =INDEX($D$17:$D$26,MATCH(Table7[[#This Row],[Customer ID]],$A$17:$A$26,0)) -> Maharashtra | R6: =INDEX($E$17:$E$26,MATCH(Table7[[#This Row],[Customer ID]],$A$17:$A$26,0)) -> Female | S6: S004 | T6: =INDEX($B$30:$B$34,MATCH(S6,$A$30:$A$34,0)) -> Digital Hub | U6: =INDEX($C$30:$C$34,MATCH(Table7[[#This Row],[Store ID]],'Advance table'!$A$30:$A$34,0)) -> Pune | V6: 1 | W6: 16000 | X6: 16000
B7: P1005 | C7: Mouse | D7: Accessories | E7: HP | H7: SA005 | I7: =INDEX(Sales[Date],MATCH(Table7[[#This Row],[Sale ID]],Sales[Sale ID],0)) -> 46027 | J7: P1002 | K7: =INDEX(C3:C12,MATCH($J7,B3:B12,0)) -> Smartphone | L7: =INDEX(D3:D12,MATCH(K7,C3:C12,0)) -> Electronics | M7: =INDEX($E$3:$E$12,MATCH(Table7[[#This Row],[Product ID]],$B$3:$B$12,0)) -> Samsung | N7: C005 | O7: =INDEX($B$17:$B$26,MATCH(N7,$A$17:$A$26,0)) -> Arjun Singh | P7: =INDEX($C$17:$C$26,MATCH(Table7[[#This Row],[Customer ID]],$A$17:$A$26,0)) -> Jaipur | Q7: =INDEX($D$17:$D$26,MATCH(Table7[[#This Row],[Customer ID]],$A$17:$A$26,0)) -> Rajasthan | R7: =INDEX($E$17:$E$26,MATCH(Table7[[#This Row],[Customer ID]],$A$17:$A$26,0)) -> Male | S7: S005 | T7: =INDEX($B$30:$B$34,MATCH(S7,$A$30:$A$34,0)) -> Smart World | U7: =INDEX($C$30:$C$34,MATCH(Table7[[#This Row],[Store ID]],'Advance table'!$A$30:$A$34,0)) -> Jaipur | V7: 2 | W7: 32000 | X7: 64000
B8: P1006 | C8: Printer | D8: Electronics | E8: Canon | H8: SA006 | I8: =INDEX(Sales[Date],MATCH(Table7[[#This Row],[Sale ID]],Sales[Sale ID],0)) -> 46028 | J8: P1007 | K8: =INDEX(C8:C17,MATCH($J8,B8:B17,0)) -> Office Chair | L8: =INDEX(D8:D17,MATCH(K8,C8:C17,0)) -> Furniture | M8: =INDEX($E$3:$E$12,MATCH(Table7[[#This Row],[Product ID]],$B$3:$B$12,0)) -> Green Soul | N8: C006 | O8: =INDEX($B$17:$B$26,MATCH(N8,$A$17:$A$26,0)) -> Neha Verma | P8: =INDEX($C$17:$C$26,MATCH(Table7[[#This Row],[Customer ID]],$A$17:$A$26,0)) -> Delhi | Q8: =INDEX($D$17:$D$26,MATCH(Table7[[#This Row],[Customer ID]],$A$17:$A$26,0)) -> Delhi | R8: =INDEX($E$17:$E$26,MATCH(Table7[[#This Row],[Customer ID]],$A$17:$A$26,0)) -> Female | S8: S001 | T8: =INDEX($B$30:$B$34,MATCH(S8,$A$30:$A$34,0)) -> Alpha Store | U8: =INDEX($C$30:$C$34,MATCH(Table7[[#This Row],[Store ID]],'Advance table'!$A$30:$A$34,0)) -> Ahmedabad | V8: 1 | W8: 8500 | X8: 8500
B9: P1007 | C9: Office Chair | D9: Furniture | E9: Green Soul | H9: SA007 | I9: =INDEX(Sales[Date],MATCH(Table7[[#This Row],[Sale ID]],Sales[Sale ID],0)) -> 46029 | J9: P1006 | K9: =INDEX(C3:C12,MATCH($J9,B3:B12,0)) -> Printer | L9: =INDEX(D3:D12,MATCH(K9,C3:C12,0)) -> Electronics | M9: =INDEX($E$3:$E$12,MATCH(Table7[[#This Row],[Product ID]],$B$3:$B$12,0)) -> Canon | N9: C007 | O9: =INDEX($B$17:$B$26,MATCH(N9,$A$17:$A$26,0)) -> Rohan Gupta | P9: =INDEX($C$17:$C$26,MATCH(Table7[[#This Row],[Customer ID]],$A$17:$A$26,0)) -> Indore | Q9: =INDEX($D$17:$D$26,MATCH(Table7[[#This Row],[Customer ID]],$A$17:$A$26,0)) -> Madhya Pradesh | R9: =INDEX($E$17:$E$26,MATCH(Table7[[#This Row],[Customer ID]],$A$17:$A$26,0)) -> Male | S9: S002 | T9: =INDEX($B$30:$B$34,MATCH(S9,$A$30:$A$34,0)) -> Beta Store | U9: =INDEX($C$30:$C$34,MATCH(Table7[[#This Row],[Store ID]],'Advance table'!$A$30:$A$34,0)) -> Surat | V9: 1 | W9: 12500 | X9: 12500
B10: P1008 | C10: Office Desk | D10: Furniture | E10: IKEA | H10: SA008 | I10: =INDEX(Sales[Date],MATCH(Table7[[#This Row],[Sale ID]],Sales[Sale ID],0)) -> 46030 | J10: P1010 | K10: =INDEX(C10:C19,MATCH($J10,B10:B19,0)) -> Webcam | L10: =INDEX(D10:D19,MATCH(K10,C10:C19,0)) -> Accessories | M10: =INDEX($E$3:$E$12,MATCH(Table7[[#This Row],[Product ID]],$B$3:$B$12,0)) -> Logitech | N10: C008 | O10: =INDEX($B$17:$B$26,MATCH(N10,$A$17:$A$26,0)) -> Pooja Sharma | P10: =INDEX($C$17:$C$26,MATCH(Table7[[#This Row],[Customer ID]],$A$17:$A$26,0)) -> Lucknow | Q10: =INDEX($D$17:$D$26,MATCH(Table7[[#This Row],[Customer ID]],$A$17:$A$26,0)) -> Uttar Pradesh | R10: =INDEX($E$17:$E$26,MATCH(Table7[[#This Row],[Customer ID]],$A$17:$A$26,0)) -> Female | S10: S003 | T10: =INDEX($B$30:$B$34,MATCH(S10,$A$30:$A$34,0)) -> Central Store | U10: =INDEX($C$30:$C$34,MATCH(Table7[[#This Row],[Store ID]],'Advance table'!$A$30:$A$34,0)) -> Mumbai | V10: 2 | W10: 3500 | X10: 7000
B11: P1009 | C11: Monitor | D11: Electronics | E11: LG | H11: SA009 | I11: =INDEX(Sales[Date],MATCH(Table7[[#This Row],[Sale ID]],Sales[Sale ID],0)) -> 46031 | J11: P1004 | K11: =INDEX(C3:C12,MATCH($J11,B3:B12,0)) -> Keyboard | L11: =INDEX(D3:D12,MATCH(K11,C3:C12,0)) -> Accessories | M11: =INDEX($E$3:$E$12,MATCH(Table7[[#This Row],[Product ID]],$B$3:$B$12,0)) -> Logitech | N11: C009 | O11: =INDEX($B$17:$B$26,MATCH(N11,$A$17:$A$26,0)) -> Karan Desai | P11: =INDEX($C$17:$C$26,MATCH(Table7[[#This Row],[Customer ID]],$A$17:$A$26,0)) -> Vadodara | Q11: =INDEX($D$17:$D$26,MATCH(Table7[[#This Row],[Customer ID]],$A$17:$A$26,0)) -> Gujarat | R11: =INDEX($E$17:$E$26,MATCH(Table7[[#This Row],[Customer ID]],$A$17:$A$26,0)) -> Male | S11: S004 | T11: =INDEX($B$30:$B$34,MATCH(S11,$A$30:$A$34,0)) -> Digital Hub | U11: =INDEX($C$30:$C$34,MATCH(Table7[[#This Row],[Store ID]],'Advance table'!$A$30:$A$34,0)) -> Pune | V11: 4 | W11: 1800 | X11: 7200
B12: P1010 | C12: Webcam | D12: Accessories | E12: Logitech | H12: SA010 | I12: =INDEX(Sales[Date],MATCH(Table7[[#This Row],[Sale ID]],Sales[Sale ID],0)) -> 46032 | J12: P1008 | K12: =INDEX(C3:C12,MATCH($J12,B3:B12,0)) -> Office Desk | L12: =INDEX($D$3:$D$12,MATCH(K12,$C$3:$C$12,0)) -> Furniture | M12: =INDEX($E$3:$E$12,MATCH(Table7[[#This Row],[Product ID]],$B$3:$B$12,0)) -> IKEA | N12: C010 | O12: =INDEX($B$17:$B$26,MATCH(N12,$A$17:$A$26,0)) -> Anjali Nair | P12: =INDEX($C$17:$C$26,MATCH(Table7[[#This Row],[Customer ID]],$A$17:$A$26,0)) -> Kochi | Q12: =INDEX($D$17:$D$26,MATCH(Table7[[#This Row],[Customer ID]],$A$17:$A$26,0)) -> Kerala | R12: =INDEX($E$17:$E$26,MATCH(Table7[[#This Row],[Customer ID]],$A$17:$A$26,0)) -> Female | S12: S005 | T12: =INDEX($B$30:$B$34,MATCH(S12,$A$30:$A$34,0)) -> Smart World | U12: =INDEX($C$30:$C$34,MATCH(Table7[[#This Row],[Store ID]],'Advance table'!$A$30:$A$34,0)) -> Jaipur | V12: 1 | W12: 12000 | X12: 12000
H13: SA011 | I13: =INDEX(Sales[Date],MATCH(Table7[[#This Row],[Sale ID]],Sales[Sale ID],0)) -> 46033 | J13: P1005 | K13: =INDEX(C3:C12,MATCH($J13,B3:B12,0)) -> Mouse | L13: =INDEX($D$3:$D$12,MATCH(K13,$C$3:$C$12,0)) -> Accessories | M13: =INDEX($E$3:$E$12,MATCH(Table7[[#This Row],[Product ID]],$B$3:$B$12,0)) -> HP | N13: C001 | O13: =INDEX($B$17:$B$26,MATCH(N13,$A$17:$A$26,0)) -> Amit Patel | P13: =INDEX($C$17:$C$26,MATCH(Table7[[#This Row],[Customer ID]],$A$17:$A$26,0)) -> Ahmedabad | Q13: =INDEX($D$17:$D$26,MATCH(Table7[[#This Row],[Customer ID]],$A$17:$A$26,0)) -> Gujarat | R13: =INDEX($E$17:$E$26,MATCH(Table7[[#This Row],[Customer ID]],$A$17:$A$26,0)) -> Male | S13: S001 | T13: =INDEX($B$30:$B$34,MATCH(S13,$A$30:$A$34,0)) -> Alpha Store | U13: =INDEX($C$30:$C$34,MATCH(Table7[[#This Row],[Store ID]],'Advance table'!$A$30:$A$34,0)) -> Ahmedabad | V13: 5 | W13: 900 | X13: 4500
H14: SA012 | I14: =INDEX(Sales[Date],MATCH(Table7[[#This Row],[Sale ID]],Sales[Sale ID],0)) -> 46034 | J14: P1003 | K14: =INDEX(C3:C12,MATCH($J14,B3:B12,0)) -> Headphones | L14: =INDEX($D$3:$D$12,MATCH(K14,$C$3:$C$12,0)) -> Electronics | M14: =INDEX($E$3:$E$12,MATCH(Table7[[#This Row],[Product ID]],$B$3:$B$12,0)) -> Sony | N14: C002 | O14: =INDEX($B$17:$B$26,MATCH(N14,$A$17:$A$26,0)) -> Priya Shah | P14: =INDEX($C$17:$C$26,MATCH(Table7[[#This Row],[Customer ID]],$A$17:$A$26,0)) -> Surat | Q14: =INDEX($D$17:$D$26,MATCH(Table7[[#This Row],[Customer ID]],$A$17:$A$26,0)) -> Gujarat | R14: =INDEX($E$17:$E$26,MATCH(Table7[[#This Row],[Customer ID]],$A$17:$A$26,0)) -> Female | S14: S002 | T14: =INDEX($B$30:$B$34,MATCH(S14,$A$30:$A$34,0)) -> Beta Store | U14: =INDEX($C$30:$C$34,MATCH(Table7[[#This Row],[Store ID]],'Advance table'!$A$30:$A$34,0)) -> Surat | V14: 3 | W14: 4500 | X14: 13500
H15: SA013 | I15: =INDEX(Sales[Date],MATCH(Table7[[#This Row],[Sale ID]],Sales[Sale ID],0)) -> 46035 | J15: P1001 | K15: =INDEX(C3:C12,MATCH($J15,B3:B12,0)) -> Laptop | L15: =INDEX($D$3:$D$12,MATCH(K15,$C$3:$C$12,0)) -> Electronics | M15: =INDEX($E$3:$E$12,MATCH(Table7[[#This Row],[Product ID]],$B$3:$B$12,0)) -> Dell | N15: C003 | O15: =INDEX($B$17:$B$26,MATCH(N15,$A$17:$A$26,0)) -> Rahul Mehta | P15: =INDEX($C$17:$C$26,MATCH(Table7[[#This Row],[Customer ID]],$A$17:$A$26,0)) -> Mumbai | Q15: =INDEX($D$17:$D$26,MATCH(Table7[[#This Row],[Customer ID]],$A$17:$A$26,0)) -> Maharashtra | R15: =INDEX($E$17:$E$26,MATCH(Table7[[#This Row],[Customer ID]],$A$17:$A$26,0)) -> Male | S15: S003 | T15: =INDEX($B$30:$B$34,MATCH(S15,$A$30:$A$34,0)) -> Central Store | U15: =INDEX($C$30:$C$34,MATCH(Table7[[#This Row],[Store ID]],'Advance table'!$A$30:$A$34,0)) -> Mumbai | V15: 1 | W15: 55000 | X15: 55000
A16: Customer ID | B16: Customer Name | C16: City | D16: State | E16: Gender | H16: SA014 | I16: =INDEX(Sales[Date],MATCH(Table7[[#This Row],[Sale ID]],Sales[Sale ID],0)) -> 46036 | J16: P1009 | K16: =INDEX(C3:C12,MATCH($J16,B3:B12,0)) -> Monitor | L16: =INDEX($D$3:$D$12,MATCH(K16,$C$3:$C$12,0)) -> Electronics | M16: =INDEX($E$3:$E$12,MATCH(Table7[[#This Row],[Product ID]],$B$3:$B$12,0)) -> LG | N16: C004 | O16: =INDEX($B$17:$B$26,MATCH(N16,$A$17:$A$26,0)) -> Sneha Joshi | P16: =INDEX($C$17:$C$26,MATCH(Table7[[#This Row],[Customer ID]],$A$17:$A$26,0)) -> Pune | Q16: =INDEX($D$17:$D$26,MATCH(Table7[[#This Row],[Customer ID]],$A$17:$A$26,0)) -> Maharashtra | R16: =INDEX($E$17:$E$26,MATCH(Table7[[#This Row],[Customer ID]],$A$17:$A$26,0)) -> Female | S16: S004 | T16: =INDEX($B$30:$B$34,MATCH(S16,$A$30:$A$34,0)) -> Digital Hub | U16: =INDEX($C$30:$C$34,MATCH(Table7[[#This Row],[Store ID]],'Advance table'!$A$30:$A$34,0)) -> Pune | V16: 2 | W16: 16000 | X16: 32000
A17: C001 | B17: Amit Patel | C17: Ahmedabad | D17: Gujarat | E17: Male | H17: SA015 | I17: =INDEX(Sales[Date],MATCH(Table7[[#This Row],[Sale ID]],Sales[Sale ID],0)) -> 46037 | J17: P1002 | K17: =INDEX(C3:C12,MATCH($J17,B3:B12,0)) -> Smartphone | L17: =INDEX($D$3:$D$12,MATCH(K17,$C$3:$C$12,0)) -> Electronics | M17: =INDEX($E$3:$E$12,MATCH(Table7[[#This Row],[Product ID]],$B$3:$B$12,0)) -> Samsung | N17: C005 | O17: =INDEX($B$17:$B$26,MATCH(N17,$A$17:$A$26,0)) -> Arjun Singh | P17: =INDEX($C$17:$C$26,MATCH(Table7[[#This Row],[Customer ID]],$A$17:$A$26,0)) -> Jaipur | Q17: =INDEX($D$17:$D$26,MATCH(Table7[[#This Row],[Customer ID]],$A$17:$A$26,0)) -> Rajasthan | R17: =INDEX($E$17:$E$26,MATCH(Table7[[#This Row],[Customer ID]],$A$17:$A$26,0)) -> Male | S17: S005 | T17: =INDEX($B$30:$B$34,MATCH(S17,$A$30:$A$34,0)) -> Smart World | U17: =INDEX($C$30:$C$34,MATCH(Table7[[#This Row],[Store ID]],'Advance table'!$A$30:$A$34,0)) -> Jaipur | V17: 1 | W17: 32000 | X17: 32000
A18: C002 | B18: Priya Shah | C18: Surat | D18: Gujarat | E18: Female
A19: C003 | B19: Rahul Mehta | C19: Mumbai | D19: Maharashtra | E19: Male
A20: C004 | B20: Sneha Joshi | C20: Pune | D20: Maharashtra | E20: Female
A21: C005 | B21: Arjun Singh | C21: Jaipur | D21: Rajasthan | E21: Male
A22: C006 | B22: Neha Verma | C22: Delhi | D22: Delhi | E22: Female
A23: C007 | B23: Rohan Gupta | C23: Indore | D23: Madhya Pradesh | E23: Male
A24: C008 | B24: Pooja Sharma | C24: Lucknow | D24: Uttar Pradesh | E24: Female
A25: C009 | B25: Karan Desai | C25: Vadodara | D25: Gujarat | E25: Male
A26: C010 | B26: Anjali Nair | C26: Kochi | D26: Kerala | E26: Female
A29: Store ID | B29: Store Name | C29: City | D29: State
A30: S001 | B30: Alpha Store | C30: Ahmedabad | D30: Gujarat
A31: S002 | B31: Beta Store | C31: Surat | D31: Gujarat
A32: S003 | B32: Central Store | C32: Mumbai | D32: Maharashtra
A33: S004 | B33: Digital Hub | C33: Pune | D33: Maharashtra
A34: S005 | B34: Smart World | C34: Jaipur | D34: Rajasthan
